2024-12-24 18:28:09,671 INFO    MainThread:106935 [wandb_setup.py:_flush():68] Current SDK version is 0.19.0
2024-12-24 18:28:09,671 INFO    MainThread:106935 [wandb_setup.py:_flush():68] Configure stats pid to 106935
2024-12-24 18:28:09,672 INFO    MainThread:106935 [wandb_setup.py:_flush():68] Loading settings from /home/anjunyi/.config/wandb/settings
2024-12-24 18:28:09,672 INFO    MainThread:106935 [wandb_setup.py:_flush():68] Loading settings from /cpfs01/projects-HDD/cfff-4405968bce88_HDD/anjunyi/mole_diffusion_sorce/df_mole/wandb/settings
2024-12-24 18:28:09,672 INFO    MainThread:106935 [wandb_setup.py:_flush():68] Loading settings from environment variables
2024-12-24 18:28:09,672 INFO    MainThread:106935 [wandb_init.py:_log_setup():528] Logging user logs to /cpfs01/projects-HDD/cfff-4405968bce88_HDD/anjunyi/mole_diffusion_sorce/df_mole/wandb/run-20241224_182809-neq8emxf/logs/debug.log
2024-12-24 18:28:09,672 INFO    MainThread:106935 [wandb_init.py:_log_setup():529] Logging internal logs to /cpfs01/projects-HDD/cfff-4405968bce88_HDD/anjunyi/mole_diffusion_sorce/df_mole/wandb/run-20241224_182809-neq8emxf/logs/debug-internal.log
2024-12-24 18:28:09,672 INFO    MainThread:106935 [wandb_init.py:init():639] calling init triggers
2024-12-24 18:28:09,672 INFO    MainThread:106935 [wandb_init.py:init():645] wandb.init called with sweep_config: {}
config: {'exp_name': 'exp_df', 'model': 'egnn_dynamics', 'probabilistic_model': 'diffusion', 'diffusion_steps': 5, 'diffusion_noise_schedule': 'polynomial_2', 'diffusion_noise_precision': 1e-05, 'diffusion_loss_type': 'l2', 'n_epochs': 3000, 'batch_size': 1024, 'lr': 0.0001, 'brute_force': False, 'actnorm': True, 'break_train_epoch': False, 'dp': True, 'condition_time': True, 'clip_grad': True, 'trace': 'hutch', 'n_layers': 9, 'inv_sublayers': 1, 'nf': 192, 'tanh': True, 'attention': True, 'norm_constant': 1, 'sin_embedding': False, 'ode_regularization': 0.001, 'dataset': 'qm9_second_half', 'datadir': 'qm9/temp', 'filter_n_atoms': None, 'dequantization': 'deterministic', 'n_report_steps': 1, 'wandb_usr': None, 'no_wandb': False, 'online': True, 'no_cuda': False, 'save_model': True, 'generate_epochs': 1, 'num_workers': 0, 'test_epochs': 50, 'data_augmentation': False, 'conditioning': ['alpha'], 'resume': None, 'start_epoch': 0, 'ema_decay': 0.999, 'augment_noise': 0, 'n_stability_samples': 500, 'normalize_factors': [1, 8, 1], 'remove_h': False, 'include_charges': False, 'visualize_every_batch': 100000000.0, 'normalization_factor': 1, 'aggregation_method': 'sum', 'cuda': True}
2024-12-24 18:28:09,672 INFO    MainThread:106935 [wandb_init.py:init():688] starting backend
2024-12-24 18:28:09,672 INFO    MainThread:106935 [wandb_init.py:init():692] sending inform_init request
2024-12-24 18:28:09,675 INFO    MainThread:106935 [backend.py:_multiprocessing_setup():104] multiprocessing start_methods=fork,spawn,forkserver, using: spawn
2024-12-24 18:28:09,676 INFO    MainThread:106935 [wandb_init.py:init():705] backend started and connected
2024-12-24 18:28:09,677 INFO    MainThread:106935 [wandb_init.py:init():798] updated telemetry
2024-12-24 18:28:09,678 INFO    MainThread:106935 [wandb_init.py:init():830] communicating run to backend with 90.0 second timeout
2024-12-24 18:29:08,607 INFO    Thread-1 (wrapped_target):106935 [retry.py:__call__():172] Retry attempt failed:
Traceback (most recent call last):
  File "/home/anjunyi/.local/lib/python3.10/site-packages/urllib3/connection.py", line 196, in _new_conn
    sock = connection.create_connection(
  File "/home/anjunyi/.local/lib/python3.10/site-packages/urllib3/util/connection.py", line 85, in create_connection
    raise err
  File "/home/anjunyi/.local/lib/python3.10/site-packages/urllib3/util/connection.py", line 73, in create_connection
    sock.connect(sa)
TimeoutError: timed out

The above exception was the direct cause of the following exception:

Traceback (most recent call last):
  File "/home/anjunyi/.local/lib/python3.10/site-packages/urllib3/connectionpool.py", line 789, in urlopen
    response = self._make_request(
  File "/home/anjunyi/.local/lib/python3.10/site-packages/urllib3/connectionpool.py", line 490, in _make_request
    raise new_e
  File "/home/anjunyi/.local/lib/python3.10/site-packages/urllib3/connectionpool.py", line 466, in _make_request
    self._validate_conn(conn)
  File "/home/anjunyi/.local/lib/python3.10/site-packages/urllib3/connectionpool.py", line 1095, in _validate_conn
    conn.connect()
  File "/home/anjunyi/.local/lib/python3.10/site-packages/urllib3/connection.py", line 615, in connect
    self.sock = sock = self._new_conn()
  File "/home/anjunyi/.local/lib/python3.10/site-packages/urllib3/connection.py", line 205, in _new_conn
    raise ConnectTimeoutError(
urllib3.exceptions.ConnectTimeoutError: (<urllib3.connection.HTTPSConnection object at 0x7fc1fd6e7280>, 'Connection to api.wandb.ai timed out. (connect timeout=20)')

The above exception was the direct cause of the following exception:

Traceback (most recent call last):
  File "/home/anjunyi/.local/lib/python3.10/site-packages/requests/adapters.py", line 667, in send
    resp = conn.urlopen(
  File "/home/anjunyi/.local/lib/python3.10/site-packages/urllib3/connectionpool.py", line 843, in urlopen
    retries = retries.increment(
  File "/home/anjunyi/.local/lib/python3.10/site-packages/urllib3/util/retry.py", line 519, in increment
    raise MaxRetryError(_pool, url, reason) from reason  # type: ignore[arg-type]
urllib3.exceptions.MaxRetryError: HTTPSConnectionPool(host='api.wandb.ai', port=443): Max retries exceeded with url: /graphql (Caused by ConnectTimeoutError(<urllib3.connection.HTTPSConnection object at 0x7fc1fd6e7280>, 'Connection to api.wandb.ai timed out. (connect timeout=20)'))

During handling of the above exception, another exception occurred:

Traceback (most recent call last):
  File "/home/anjunyi/.local/lib/python3.10/site-packages/wandb/sdk/lib/retry.py", line 131, in __call__
    result = self._call_fn(*args, **kwargs)
  File "/home/anjunyi/.local/lib/python3.10/site-packages/wandb/sdk/internal/internal_api.py", line 393, in execute
    return self.client.execute(*args, **kwargs)  # type: ignore
  File "/home/anjunyi/.local/lib/python3.10/site-packages/wandb/vendor/gql-0.2.0/wandb_gql/client.py", line 52, in execute
    result = self._get_result(document, *args, **kwargs)
  File "/home/anjunyi/.local/lib/python3.10/site-packages/wandb/vendor/gql-0.2.0/wandb_gql/client.py", line 60, in _get_result
    return self.transport.execute(document, *args, **kwargs)
  File "/home/anjunyi/.local/lib/python3.10/site-packages/wandb/sdk/lib/gql_request.py", line 58, in execute
    request = self.session.post(self.url, **post_args)
  File "/home/anjunyi/.local/lib/python3.10/site-packages/requests/sessions.py", line 637, in post
    return self.request("POST", url, data=data, json=json, **kwargs)
  File "/home/anjunyi/.local/lib/python3.10/site-packages/requests/sessions.py", line 589, in request
    resp = self.send(prep, **send_kwargs)
  File "/home/anjunyi/.local/lib/python3.10/site-packages/requests/sessions.py", line 703, in send
    r = adapter.send(request, **kwargs)
  File "/home/anjunyi/.local/lib/python3.10/site-packages/requests/adapters.py", line 688, in send
    raise ConnectTimeout(e, request=request)
requests.exceptions.ConnectTimeout: HTTPSConnectionPool(host='api.wandb.ai', port=443): Max retries exceeded with url: /graphql (Caused by ConnectTimeoutError(<urllib3.connection.HTTPSConnection object at 0x7fc1fd6e7280>, 'Connection to api.wandb.ai timed out. (connect timeout=20)'))
2024-12-24 18:29:39,711 ERROR   MainThread:106935 [wandb_init.py:init():857] encountered error: Run initialization has timed out after 90.0 sec. Please try increasing the timeout with the `init_timeout` setting: `wandb.init(settings=wandb.Settings(init_timeout=120))`.
2024-12-24 18:29:39,711 ERROR   MainThread:106935 [wandb_init.py:init():1315] error in wandb.init()
Traceback (most recent call last):
  File "/home/anjunyi/.local/lib/python3.10/site-packages/wandb/sdk/wandb_init.py", line 1305, in init
    return wi.init()
  File "/home/anjunyi/.local/lib/python3.10/site-packages/wandb/sdk/wandb_init.py", line 863, in init
    raise error
wandb.errors.errors.CommError: Run initialization has timed out after 90.0 sec. Please try increasing the timeout with the `init_timeout` setting: `wandb.init(settings=wandb.Settings(init_timeout=120))`.
2024-12-24 18:29:39,717 WARNING MsgRouterThr:106935 [router.py:message_loop():75] message_loop has been closed
